Traceback (most recent call last):
  File "/opt/hostedtoolcache/Python/3.8.6/x64/lib/python3.8/site-packages/jupyter_cache/executors/utils.py", line 51, in single_nb_execution
    executenb(
  File "/opt/hostedtoolcache/Python/3.8.6/x64/lib/python3.8/site-packages/nbclient/client.py", line 1087, in execute
    return NotebookClient(nb=nb, resources=resources, km=km, **kwargs).execute()
  File "/opt/hostedtoolcache/Python/3.8.6/x64/lib/python3.8/site-packages/nbclient/util.py", line 74, in wrapped
    return just_run(coro(*args, **kwargs))
  File "/opt/hostedtoolcache/Python/3.8.6/x64/lib/python3.8/site-packages/nbclient/util.py", line 53, in just_run
    return loop.run_until_complete(coro)
  File "/opt/hostedtoolcache/Python/3.8.6/x64/lib/python3.8/asyncio/base_events.py", line 616, in run_until_complete
    return future.result()
  File "/opt/hostedtoolcache/Python/3.8.6/x64/lib/python3.8/site-packages/nbclient/client.py", line 540, in async_execute
    await self.async_execute_cell(
  File "/opt/hostedtoolcache/Python/3.8.6/x64/lib/python3.8/site-packages/nbclient/client.py", line 832, in async_execute_cell
    self._check_raise_for_error(cell, exec_reply)
  File "/opt/hostedtoolcache/Python/3.8.6/x64/lib/python3.8/site-packages/nbclient/client.py", line 740, in _check_raise_for_error
    raise CellExecutionError.from_cell_and_msg(cell, exec_reply['content'])
nbclient.exceptions.CellExecutionError: An error occurred while executing the following cell:
------------------
import requests

url = "http://mlr.cs.umass.edu/ml/machine-learning-databases/adult/adult.data"
request = requests.get(url)
request.raise_for_status()
with open('adult.csv', 'w') as f:
    f.write(request.text)

### now the data is available in the file adult.csv. 
### read the questions below
# import pandas as pd
# pd.read_csv('adult.csv')    
------------------

[0;31m---------------------------------------------------------------------------[0m
[0;31mgaierror[0m                                  Traceback (most recent call last)
[0;32m/opt/hostedtoolcache/Python/3.8.6/x64/lib/python3.8/site-packages/urllib3/connection.py[0m in [0;36m_new_conn[0;34m(self)[0m
[1;32m    158[0m         [0;32mtry[0m[0;34m:[0m[0;34m[0m[0;34m[0m[0m
[0;32m--> 159[0;31m             conn = connection.create_connection(
[0m[1;32m    160[0m                 [0;34m([0m[0mself[0m[0;34m.[0m[0m_dns_host[0m[0;34m,[0m [0mself[0m[0;34m.[0m[0mport[0m[0;34m)[0m[0;34m,[0m [0mself[0m[0;34m.[0m[0mtimeout[0m[0;34m,[0m [0;34m**[0m[0mextra_kw[0m[0;34m[0m[0;34m[0m[0m

[0;32m/opt/hostedtoolcache/Python/3.8.6/x64/lib/python3.8/site-packages/urllib3/util/connection.py[0m in [0;36mcreate_connection[0;34m(address, timeout, source_address, socket_options)[0m
[1;32m     60[0m [0;34m[0m[0m
[0;32m---> 61[0;31m     [0;32mfor[0m [0mres[0m [0;32min[0m [0msocket[0m[0;34m.[0m[0mgetaddrinfo[0m[0;34m([0m[0mhost[0m[0;34m,[0m [0mport[0m[0;34m,[0m [0mfamily[0m[0;34m,[0m [0msocket[0m[0;34m.[0m[0mSOCK_STREAM[0m[0;34m)[0m[0;34m:[0m[0;34m[0m[0;34m[0m[0m
[0m[1;32m     62[0m         [0maf[0m[0;34m,[0m [0msocktype[0m[0;34m,[0m [0mproto[0m[0;34m,[0m [0mcanonname[0m[0;34m,[0m [0msa[0m [0;34m=[0m [0mres[0m[0;34m[0m[0;34m[0m[0m

[0;32m/opt/hostedtoolcache/Python/3.8.6/x64/lib/python3.8/socket.py[0m in [0;36mgetaddrinfo[0;34m(host, port, family, type, proto, flags)[0m
[1;32m    917[0m     [0maddrlist[0m [0;34m=[0m [0;34m[[0m[0;34m][0m[0;34m[0m[0;34m[0m[0m
[0;32m--> 918[0;31m     [0;32mfor[0m [0mres[0m [0;32min[0m [0m_socket[0m[0;34m.[0m[0mgetaddrinfo[0m[0;34m([0m[0mhost[0m[0;34m,[0m [0mport[0m[0;34m,[0m [0mfamily[0m[0;34m,[0m [0mtype[0m[0;34m,[0m [0mproto[0m[0;34m,[0m [0mflags[0m[0;34m)[0m[0;34m:[0m[0;34m[0m[0;34m[0m[0m
[0m[1;32m    919[0m         [0maf[0m[0;34m,[0m [0msocktype[0m[0;34m,[0m [0mproto[0m[0;34m,[0m [0mcanonname[0m[0;34m,[0m [0msa[0m [0;34m=[0m [0mres[0m[0;34m[0m[0;34m[0m[0m

[0;31mgaierror[0m: [Errno -2] Name or service not known

During handling of the above exception, another exception occurred:

[0;31mNewConnectionError[0m                        Traceback (most recent call last)
[0;32m/opt/hostedtoolcache/Python/3.8.6/x64/lib/python3.8/site-packages/urllib3/connectionpool.py[0m in [0;36murlopen[0;34m(self, method, url, body, headers, retries, redirect, assert_same_host, timeout, pool_timeout, release_conn, chunked, body_pos, **response_kw)[0m
[1;32m    669[0m             [0;31m# Make the request on the httplib connection object.[0m[0;34m[0m[0;34m[0m[0;34m[0m[0m
[0;32m--> 670[0;31m             httplib_response = self._make_request(
[0m[1;32m    671[0m                 [0mconn[0m[0;34m,[0m[0;34m[0m[0;34m[0m[0m

[0;32m/opt/hostedtoolcache/Python/3.8.6/x64/lib/python3.8/site-packages/urllib3/connectionpool.py[0m in [0;36m_make_request[0;34m(self, conn, method, url, timeout, chunked, **httplib_request_kw)[0m
[1;32m    391[0m         [0;32melse[0m[0;34m:[0m[0;34m[0m[0;34m[0m[0m
[0;32m--> 392[0;31m             [0mconn[0m[0;34m.[0m[0mrequest[0m[0;34m([0m[0mmethod[0m[0;34m,[0m [0murl[0m[0;34m,[0m [0;34m**[0m[0mhttplib_request_kw[0m[0;34m)[0m[0;34m[0m[0;34m[0m[0m
[0m[1;32m    393[0m [0;34m[0m[0m

[0;32m/opt/hostedtoolcache/Python/3.8.6/x64/lib/python3.8/http/client.py[0m in [0;36mrequest[0;34m(self, method, url, body, headers, encode_chunked)[0m
[1;32m   1254[0m         [0;34m"""Send a complete request to the server."""[0m[0;34m[0m[0;34m[0m[0m
[0;32m-> 1255[0;31m         [0mself[0m[0;34m.[0m[0m_send_request[0m[0;34m([0m[0mmethod[0m[0;34m,[0m [0murl[0m[0;34m,[0m [0mbody[0m[0;34m,[0m [0mheaders[0m[0;34m,[0m [0mencode_chunked[0m[0;34m)[0m[0;34m[0m[0;34m[0m[0m
[0m[1;32m   1256[0m [0;34m[0m[0m

[0;32m/opt/hostedtoolcache/Python/3.8.6/x64/lib/python3.8/http/client.py[0m in [0;36m_send_request[0;34m(self, method, url, body, headers, encode_chunked)[0m
[1;32m   1300[0m             [0mbody[0m [0;34m=[0m [0m_encode[0m[0;34m([0m[0mbody[0m[0;34m,[0m [0;34m'body'[0m[0;34m)[0m[0;34m[0m[0;34m[0m[0m
[0;32m-> 1301[0;31m         [0mself[0m[0;34m.[0m[0mendheaders[0m[0;34m([0m[0mbody[0m[0;34m,[0m [0mencode_chunked[0m[0;34m=[0m[0mencode_chunked[0m[0;34m)[0m[0;34m[0m[0;34m[0m[0m
[0m[1;32m   1302[0m [0;34m[0m[0m

[0;32m/opt/hostedtoolcache/Python/3.8.6/x64/lib/python3.8/http/client.py[0m in [0;36mendheaders[0;34m(self, message_body, encode_chunked)[0m
[1;32m   1249[0m             [0;32mraise[0m [0mCannotSendHeader[0m[0;34m([0m[0;34m)[0m[0;34m[0m[0;34m[0m[0m
[0;32m-> 1250[0;31m         [0mself[0m[0;34m.[0m[0m_send_output[0m[0;34m([0m[0mmessage_body[0m[0;34m,[0m [0mencode_chunked[0m[0;34m=[0m[0mencode_chunked[0m[0;34m)[0m[0;34m[0m[0;34m[0m[0m
[0m[1;32m   1251[0m [0;34m[0m[0m

[0;32m/opt/hostedtoolcache/Python/3.8.6/x64/lib/python3.8/http/client.py[0m in [0;36m_send_output[0;34m(self, message_body, encode_chunked)[0m
[1;32m   1009[0m         [0;32mdel[0m [0mself[0m[0;34m.[0m[0m_buffer[0m[0;34m[[0m[0;34m:[0m[0;34m][0m[0;34m[0m[0;34m[0m[0m
[0;32m-> 1010[0;31m         [0mself[0m[0;34m.[0m[0msend[0m[0;34m([0m[0mmsg[0m[0;34m)[0m[0;34m[0m[0;34m[0m[0m
[0m[1;32m   1011[0m [0;34m[0m[0m

[0;32m/opt/hostedtoolcache/Python/3.8.6/x64/lib/python3.8/http/client.py[0m in [0;36msend[0;34m(self, data)[0m
[1;32m    949[0m             [0;32mif[0m [0mself[0m[0;34m.[0m[0mauto_open[0m[0;34m:[0m[0;34m[0m[0;34m[0m[0m
[0;32m--> 950[0;31m                 [0mself[0m[0;34m.[0m[0mconnect[0m[0;34m([0m[0;34m)[0m[0;34m[0m[0;34m[0m[0m
[0m[1;32m    951[0m             [0;32melse[0m[0;34m:[0m[0;34m[0m[0;34m[0m[0m

[0;32m/opt/hostedtoolcache/Python/3.8.6/x64/lib/python3.8/site-packages/urllib3/connection.py[0m in [0;36mconnect[0;34m(self)[0m
[1;32m    186[0m     [0;32mdef[0m [0mconnect[0m[0;34m([0m[0mself[0m[0;34m)[0m[0;34m:[0m[0;34m[0m[0;34m[0m[0m
[0;32m--> 187[0;31m         [0mconn[0m [0;34m=[0m [0mself[0m[0;34m.[0m[0m_new_conn[0m[0;34m([0m[0;34m)[0m[0;34m[0m[0;34m[0m[0m
[0m[1;32m    188[0m         [0mself[0m[0;34m.[0m[0m_prepare_conn[0m[0;34m([0m[0mconn[0m[0;34m)[0m[0;34m[0m[0;34m[0m[0m

[0;32m/opt/hostedtoolcache/Python/3.8.6/x64/lib/python3.8/site-packages/urllib3/connection.py[0m in [0;36m_new_conn[0;34m(self)[0m
[1;32m    170[0m         [0;32mexcept[0m [0mSocketError[0m [0;32mas[0m [0me[0m[0;34m:[0m[0;34m[0m[0;34m[0m[0m
[0;32m--> 171[0;31m             raise NewConnectionError(
[0m[1;32m    172[0m                 [0mself[0m[0;34m,[0m [0;34m"Failed to establish a new connection: %s"[0m [0;34m%[0m [0me[0m[0;34m[0m[0;34m[0m[0m

[0;31mNewConnectionError[0m: <urllib3.connection.HTTPConnection object at 0x7f200bb5c0d0>: Failed to establish a new connection: [Errno -2] Name or service not known

During handling of the above exception, another exception occurred:

[0;31mMaxRetryError[0m                             Traceback (most recent call last)
[0;32m/opt/hostedtoolcache/Python/3.8.6/x64/lib/python3.8/site-packages/requests/adapters.py[0m in [0;36msend[0;34m(self, request, stream, timeout, verify, cert, proxies)[0m
[1;32m    438[0m             [0;32mif[0m [0;32mnot[0m [0mchunked[0m[0;34m:[0m[0;34m[0m[0;34m[0m[0m
[0;32m--> 439[0;31m                 resp = conn.urlopen(
[0m[1;32m    440[0m                     [0mmethod[0m[0;34m=[0m[0mrequest[0m[0;34m.[0m[0mmethod[0m[0;34m,[0m[0;34m[0m[0;34m[0m[0m

[0;32m/opt/hostedtoolcache/Python/3.8.6/x64/lib/python3.8/site-packages/urllib3/connectionpool.py[0m in [0;36murlopen[0;34m(self, method, url, body, headers, retries, redirect, assert_same_host, timeout, pool_timeout, release_conn, chunked, body_pos, **response_kw)[0m
[1;32m    725[0m [0;34m[0m[0m
[0;32m--> 726[0;31m             retries = retries.increment(
[0m[1;32m    727[0m                 [0mmethod[0m[0;34m,[0m [0murl[0m[0;34m,[0m [0merror[0m[0;34m=[0m[0me[0m[0;34m,[0m [0m_pool[0m[0;34m=[0m[0mself[0m[0;34m,[0m [0m_stacktrace[0m[0;34m=[0m[0msys[0m[0;34m.[0m[0mexc_info[0m[0;34m([0m[0;34m)[0m[0;34m[[0m[0;36m2[0m[0;34m][0m[0;34m[0m[0;34m[0m[0m

[0;32m/opt/hostedtoolcache/Python/3.8.6/x64/lib/python3.8/site-packages/urllib3/util/retry.py[0m in [0;36mincrement[0;34m(self, method, url, response, error, _pool, _stacktrace)[0m
[1;32m    438[0m         [0;32mif[0m [0mnew_retry[0m[0;34m.[0m[0mis_exhausted[0m[0;34m([0m[0;34m)[0m[0;34m:[0m[0;34m[0m[0;34m[0m[0m
[0;32m--> 439[0;31m             [0;32mraise[0m [0mMaxRetryError[0m[0;34m([0m[0m_pool[0m[0;34m,[0m [0murl[0m[0;34m,[0m [0merror[0m [0;32mor[0m [0mResponseError[0m[0;34m([0m[0mcause[0m[0;34m)[0m[0;34m)[0m[0;34m[0m[0;34m[0m[0m
[0m[1;32m    440[0m [0;34m[0m[0m

[0;31mMaxRetryError[0m: HTTPConnectionPool(host='mlr.cs.umass.edu', port=80): Max retries exceeded with url: /ml/machine-learning-databases/adult/adult.data (Caused by NewConnectionError('<urllib3.connection.HTTPConnection object at 0x7f200bb5c0d0>: Failed to establish a new connection: [Errno -2] Name or service not known'))

During handling of the above exception, another exception occurred:

[0;31mConnectionError[0m                           Traceback (most recent call last)
[0;32m<ipython-input-2-83fe6576a1c2>[0m in [0;36m<module>[0;34m[0m
[1;32m      2[0m [0;34m[0m[0m
[1;32m      3[0m [0murl[0m [0;34m=[0m [0;34m"http://mlr.cs.umass.edu/ml/machine-learning-databases/adult/adult.data"[0m[0;34m[0m[0;34m[0m[0m
[0;32m----> 4[0;31m [0mrequest[0m [0;34m=[0m [0mrequests[0m[0;34m.[0m[0mget[0m[0;34m([0m[0murl[0m[0;34m)[0m[0;34m[0m[0;34m[0m[0m
[0m[1;32m      5[0m [0mrequest[0m[0;34m.[0m[0mraise_for_status[0m[0;34m([0m[0;34m)[0m[0;34m[0m[0;34m[0m[0m
[1;32m      6[0m [0;32mwith[0m [0mopen[0m[0;34m([0m[0;34m'adult.csv'[0m[0;34m,[0m [0;34m'w'[0m[0;34m)[0m [0;32mas[0m [0mf[0m[0;34m:[0m[0;34m[0m[0;34m[0m[0m

[0;32m/opt/hostedtoolcache/Python/3.8.6/x64/lib/python3.8/site-packages/requests/api.py[0m in [0;36mget[0;34m(url, params, **kwargs)[0m
[1;32m     74[0m [0;34m[0m[0m
[1;32m     75[0m     [0mkwargs[0m[0;34m.[0m[0msetdefault[0m[0;34m([0m[0;34m'allow_redirects'[0m[0;34m,[0m [0;32mTrue[0m[0;34m)[0m[0;34m[0m[0;34m[0m[0m
[0;32m---> 76[0;31m     [0;32mreturn[0m [0mrequest[0m[0;34m([0m[0;34m'get'[0m[0;34m,[0m [0murl[0m[0;34m,[0m [0mparams[0m[0;34m=[0m[0mparams[0m[0;34m,[0m [0;34m**[0m[0mkwargs[0m[0;34m)[0m[0;34m[0m[0;34m[0m[0m
[0m[1;32m     77[0m [0;34m[0m[0m
[1;32m     78[0m [0;34m[0m[0m

[0;32m/opt/hostedtoolcache/Python/3.8.6/x64/lib/python3.8/site-packages/requests/api.py[0m in [0;36mrequest[0;34m(method, url, **kwargs)[0m
[1;32m     59[0m     [0;31m# cases, and look like a memory leak in others.[0m[0;34m[0m[0;34m[0m[0;34m[0m[0m
[1;32m     60[0m     [0;32mwith[0m [0msessions[0m[0;34m.[0m[0mSession[0m[0;34m([0m[0;34m)[0m [0;32mas[0m [0msession[0m[0;34m:[0m[0;34m[0m[0;34m[0m[0m
[0;32m---> 61[0;31m         [0;32mreturn[0m [0msession[0m[0;34m.[0m[0mrequest[0m[0;34m([0m[0mmethod[0m[0;34m=[0m[0mmethod[0m[0;34m,[0m [0murl[0m[0;34m=[0m[0murl[0m[0;34m,[0m [0;34m**[0m[0mkwargs[0m[0;34m)[0m[0;34m[0m[0;34m[0m[0m
[0m[1;32m     62[0m [0;34m[0m[0m
[1;32m     63[0m [0;34m[0m[0m

[0;32m/opt/hostedtoolcache/Python/3.8.6/x64/lib/python3.8/site-packages/requests/sessions.py[0m in [0;36mrequest[0;34m(self, method, url, params, data, headers, cookies, files, auth, timeout, allow_redirects, proxies, hooks, stream, verify, cert, json)[0m
[1;32m    528[0m         }
[1;32m    529[0m         [0msend_kwargs[0m[0;34m.[0m[0mupdate[0m[0;34m([0m[0msettings[0m[0;34m)[0m[0;34m[0m[0;34m[0m[0m
[0;32m--> 530[0;31m         [0mresp[0m [0;34m=[0m [0mself[0m[0;34m.[0m[0msend[0m[0;34m([0m[0mprep[0m[0;34m,[0m [0;34m**[0m[0msend_kwargs[0m[0;34m)[0m[0;34m[0m[0;34m[0m[0m
[0m[1;32m    531[0m [0;34m[0m[0m
[1;32m    532[0m         [0;32mreturn[0m [0mresp[0m[0;34m[0m[0;34m[0m[0m

[0;32m/opt/hostedtoolcache/Python/3.8.6/x64/lib/python3.8/site-packages/requests/sessions.py[0m in [0;36msend[0;34m(self, request, **kwargs)[0m
[1;32m    641[0m [0;34m[0m[0m
[1;32m    642[0m         [0;31m# Send the request[0m[0;34m[0m[0;34m[0m[0;34m[0m[0m
[0;32m--> 643[0;31m         [0mr[0m [0;34m=[0m [0madapter[0m[0;34m.[0m[0msend[0m[0;34m([0m[0mrequest[0m[0;34m,[0m [0;34m**[0m[0mkwargs[0m[0;34m)[0m[0;34m[0m[0;34m[0m[0m
[0m[1;32m    644[0m [0;34m[0m[0m
[1;32m    645[0m         [0;31m# Total elapsed time of the request (approximately)[0m[0;34m[0m[0;34m[0m[0;34m[0m[0m

[0;32m/opt/hostedtoolcache/Python/3.8.6/x64/lib/python3.8/site-packages/requests/adapters.py[0m in [0;36msend[0;34m(self, request, stream, timeout, verify, cert, proxies)[0m
[1;32m    514[0m                 [0;32mraise[0m [0mSSLError[0m[0;34m([0m[0me[0m[0;34m,[0m [0mrequest[0m[0;34m=[0m[0mrequest[0m[0;34m)[0m[0;34m[0m[0;34m[0m[0m
[1;32m    515[0m [0;34m[0m[0m
[0;32m--> 516[0;31m             [0;32mraise[0m [0mConnectionError[0m[0;34m([0m[0me[0m[0;34m,[0m [0mrequest[0m[0;34m=[0m[0mrequest[0m[0;34m)[0m[0;34m[0m[0;34m[0m[0m
[0m[1;32m    517[0m [0;34m[0m[0m
[1;32m    518[0m         [0;32mexcept[0m [0mClosedPoolError[0m [0;32mas[0m [0me[0m[0;34m:[0m[0;34m[0m[0;34m[0m[0m

[0;31mConnectionError[0m: HTTPConnectionPool(host='mlr.cs.umass.edu', port=80): Max retries exceeded with url: /ml/machine-learning-databases/adult/adult.data (Caused by NewConnectionError('<urllib3.connection.HTTPConnection object at 0x7f200bb5c0d0>: Failed to establish a new connection: [Errno -2] Name or service not known'))
ConnectionError: HTTPConnectionPool(host='mlr.cs.umass.edu', port=80): Max retries exceeded with url: /ml/machine-learning-databases/adult/adult.data (Caused by NewConnectionError('<urllib3.connection.HTTPConnection object at 0x7f200bb5c0d0>: Failed to establish a new connection: [Errno -2] Name or service not known'))

